Workbook

Sheet Dashboard
A1: How people use AI at school and at work
A3: Survey of students and professionals across 12 countries | cleaned and analyzed in this workbook | all figures are live formulas
A5: USERS SURVEYED | E5: AI HOURS PER DAY | I5: HOURS SAVED A WEEK | M5: SATISFACTION | Q5: WOULD RECOMMEND | U5: PAY FOR AI
A6: =COUNTA(Clean_Data!$A$2:$A$289) -> 288 | E6: =AVERAGE(Clean_Data!$M$2:$M$289) -> 2.87 | I6: =AVERAGE(Clean_Data!$U$2:$U$289) -> 5.8100719 | M6: =AVERAGE(Clean_Data!$T$2:$T$289) -> 6.1316726 | Q6: =COUNTIFS(Clean_Data!$W$2:$W$289,"Yes")/(COUNTIFS(Clean_Data!$W$2:$W$289,"Yes")+COUNTIFS(Clean_Data!$W$2:$W$289,"Maybe")+COUNTIFS(Clean_Data!$W$2:$W$289,"No")) -> 0.60070671 | U6: =COUNTIFS(Clean_Data!$Q$2:$Q$289,"Paid")/(COUNTIFS(Clean_Data!$Q$2:$Q$289,"Paid")+COUNTIFS(Clean_Data!$Q$2:$Q$289,"Free")) -> 0.4673913
A8: =TEXT(COUNTIFS(Clean_Data!$F$2:$F$289,"Student")/COUNTA(Clean_Data!$A$2:$A$289),"0%")&" students, "&TEXT(COUNTIFS(Clean_Data!$F$2:$F$289,"Professional")/COUNTA(Clean_Data!$A$2:$A$289),"0%")&" professionals" -> 52% students, 48% professionals | E8: average per user | I8: average per user | M8: average score | Q8: answered Yes | U8: on a paid plan
A10: What the data says
A11: ="Tool race: "&INDEX(Analysis!$A$6:$A$13,MATCH(MAX(Analysis!$B$6:$B$13),Analysis!$B$6:$B$13,0))&" is used by "&TEXT(MAX(Analysis!$B$6:$B$13)/SUM(Analysis!$B$6:$B$13),"0%")&" of people. Highest satisfaction among tools with 15+ users: "&INDEX(Analysis!$A$6:$A$13,MATCH(1,INDEX((Analysis!$B$6:$B$13>=15)*(Analysis!$D$6:$D$13=MAX(INDEX((Analysis!$B$6:$B$13>=15)*Analysis!$D$6:$D$13,0))),0),0))&"." -> Tool race: ChatGPT is used by 43% of people. Highest satisfaction among tools with 15+ users: Microsoft Copilot.
A12: ="Students vs professionals: professionals report "&TEXT(Analysis!$C$38,"0.0")&" hrs saved per week, students "&TEXT(Analysis!$B$38,"0.0")&". Average AI use per day: "&TEXT(Analysis!$C$33,"0.0")&" hrs (professionals) vs "&TEXT(Analysis!$B$33,"0.0")&" hrs (students)." -> Students vs professionals: professionals report 5.6 hrs saved per week, students 6.0. Average AI use per day: 2.7 hrs (professionals) vs 3.0 hrs (students).
A13: ="Money: "&TEXT(Analysis!$B$68/(Analysis!$B$68+Analysis!$B$69),"0%")&" of users pay nothing. Paid-plan satisfaction averages "&TEXT(Analysis!$D$69,"0.0")&" vs "&TEXT(Analysis!$D$68,"0.0")&" on free plans." -> Money: 53% of users pay nothing. Paid-plan satisfaction averages 6.0 vs 6.2 on free plans.
A14: ="Time vs payoff: AI hours per day and hours saved per week have a "&LOWER(Analysis!$C$92)&" link (r = "&TEXT(Analysis!$B$92,"0.00")&"). Productivity and satisfaction: "&LOWER(Analysis!$C$94)&" (r = "&TEXT(Analysis!$B$94,"0.00")&")." -> Time vs payoff: AI hours per day and hours saved per week have a strong positive link (r = 0.90). Productivity and satisfaction: strong positive (r = 0.66).
A67: Source: AI_Usage_and_Impact_on_Students_and_Professionals.csv (300 rows, 288 after removing duplicates). Open the Cleaning_Log tab for every change made.

Sheet Analysis
A1: Analysis tables
A2: Every number below is a live formula on the Clean_Data sheet. These tables feed the Dashboard charts. Blank answers are ignored in averages.
A4: 1. AI tools: adoption and results
A5: AI Tool | B5: Users | C5: Share of Tool Answers | D5: Avg Satisfaction (1-10) | E5: Avg Productivity (1-10) | F5: Avg Accuracy (1-5) | G5: % Would Recommend (Yes) | H5: Avg Hrs Saved / Week
A6: ChatGPT | B6: =COUNTIFS(Clean_Data!$K$2:$K$289,$A6) -> 119 | C6: =B6/SUM(B$6:B$13) -> 0.42805755 | D6: =IFERROR(AVERAGEIFS(Clean_Data!$T$2:$T$289,Clean_Data!$K$2:$K$289,$A6),"") -> 6.2608696 | E6: =IFERROR(AVERAGEIFS(Clean_Data!$R$2:$R$289,Clean_Data!$K$2:$K$289,$A6),"") -> 5.2318584 | F6: =IFERROR(AVERAGEIFS(Clean_Data!$S$2:$S$289,Clean_Data!$K$2:$K$289,$A6),"") -> 3.3596491 | G6: =IFERROR(COUNTIFS(Clean_Data!$K$2:$K$289,$A6,Clean_Data!$W$2:$W$289,"Yes")/(COUNTIFS(Clean_Data!$K$2:$K$289,$A6,Clean_Data!$W$2:$W$289,"Yes")+COUNTIFS(Clean_Data!$K$2:$K$289,$A6,Clean_Data!$W$2:$W$289,"Maybe")+COUNTIFS(Clean_Data!$K$2:$K$289,$A6,Clean_Data!$W$2:$W$289,"No")),"") -> 0.58974359 | H6: =IFERROR(AVERAGEIFS(Clean_Data!$U$2:$U$289,Clean_Data!$K$2:$K$289,$A6),"") -> 5.9482759
A7: Google Gemini | B7: =COUNTIFS(Clean_Data!$K$2:$K$289,$A7) -> 39 | C7: =B7/SUM(B$6:B$13) -> 0.14028777 | D7: =IFERROR(AVERAGEIFS(Clean_Data!$T$2:$T$289,Clean_Data!$K$2:$K$289,$A7),"") -> 5.6842105 | E7: =IFERROR(AVERAGEIFS(Clean_Data!$R$2:$R$289,Clean_Data!$K$2:$K$289,$A7),"") -> 5.0605263 | F7: =IFERROR(AVERAGEIFS(Clean_Data!$S$2:$S$289,Clean_Data!$K$2:$K$289,$A7),"") -> 3.3611111 | G7: =IFERROR(COUNTIFS(Clean_Data!$K$2:$K$289,$A7,Clean_Data!$W$2:$W$289,"Yes")/(COUNTIFS(Clean_Data!$K$2:$K$289,$A7,Clean_Data!$W$2:$W$289,"Yes")+COUNTIFS(Clean_Data!$K$2:$K$289,$A7,Clean_Data!$W$2:$W$289,"Maybe")+COUNTIFS(Clean_Data!$K$2:$K$289,$A7,Clean_Data!$W$2:$W$289,"No")),"") -> 0.66666667 | H7: =IFERROR(AVERAGEIFS(Clean_Data!$U$2:$U$289,Clean_Data!$K$2:$K$289,$A7),"") -> 5.3947368
A8: Microsoft Copilot | B8: =COUNTIFS(Clean_Data!$K$2:$K$289,$A8) -> 33 | C8: =B8/SUM(B$6:B$13) -> 0.11870504 | D8: =IFERROR(AVERAGEIFS(Clean_Data!$T$2:$T$289,Clean_Data!$K$2:$K$289,$A8),"") -> 6.3030303 | E8: =IFERROR(AVERAGEIFS(Clean_Data!$R$2:$R$289,Clean_Data!$K$2:$K$289,$A8),"") -> 5.5129032 | F8: =IFERROR(AVERAGEIFS(Clean_Data!$S$2:$S$289,Clean_Data!$K$2:$K$289,$A8),"") -> 3.3939394 | G8: =IFERROR(COUNTIFS(Clean_Data!$K$2:$K$289,$A8,Clean_Data!$W$2:$W$289,"Yes")/(COUNTIFS(Clean_Data!$K$2:$K$289,$A8,Clean_Data!$W$2:$W$289,"Yes")+COUNTIFS(Clean_Data!$K$2:$K$289,$A8,Clean_Data!$W$2:$W$289,"Maybe")+COUNTIFS(Clean_Data!$K$2:$K$289,$A8,Clean_Data!$W$2:$W$289,"No")),"") -> 0.5625 | H8: =IFERROR(AVERAGEIFS(Clean_Data!$U$2:$U$289,Clean_Data!$K$2:$K$289,$A8),"") -> 6.575
A9: Claude | B9: =COUNTIFS(Clean_Data!$K$2:$K$289,$A9) -> 31 | C9: =B9/SUM(B$6:B$13) -> 0.11151079 | D9: =IFERROR(AVERAGEIFS(Clean_Data!$T$2:$T$289,Clean_Data!$K$2:$K$289,$A9),"") -> 6.0967742 | E9: =IFERROR(AVERAGEIFS(Clean_Data!$R$2:$R$289,Clean_Data!$K$2:$K$289,$A9),"") -> 5.2931034 | F9: =IFERROR(AVERAGEIFS(Clean_Data!$S$2:$S$289,Clean_Data!$K$2:$K$289,$A9),"") -> 3.3703704 | G9: =IFERROR(COUNTIFS(Clean_Data!$K$2:$K$289,$A9,Clean_Data!$W$2:$W$289,"Yes")/(COUNTIFS(Clean_Data!$K$2:$K$289,$A9,Clean_Data!$W$2:$W$289,"Yes")+COUNTIFS(Clean_Data!$K$2:$K$289,$A9,Clean_Data!$W$2:$W$289,"Maybe")+COUNTIFS(Clean_Data!$K$2:$K$289,$A9,Clean_Data!$W$2:$W$289,"No")),"") -> 0.61290323 | H9: =IFERROR(AVERAGEIFS(Clean_Data!$U$2:$U$289,Clean_Data!$K$2:$K$289,$A9),"") -> 5.6137931
A10: Perplexity AI | B10: =COUNTIFS(Clean_Data!$K$2:$K$289,$A10) -> 23 | C10: =B10/SUM(B$6:B$13) -> 0.082733813 | D10: =IFERROR(AVERAGEIFS(Clean_Data!$T$2:$T$289,Clean_Data!$K$2:$K$289,$A10),"") -> 5.8181818 | E10: =IFERROR(AVERAGEIFS(Clean_Data!$R$2:$R$289,Clean_Data!$K$2:$K$289,$A10),"") -> 4.64 | F10: =IFERROR(AVERAGEIFS(Clean_Data!$S$2:$S$289,Clean_Data!$K$2:$K$289,$A10),"") -> 3.4090909 | G10: =IFERROR(COUNTIFS(Clean_Data!$K$2:$K$289,$A10,Clean_Data!$W$2:$W$289,"Yes")/(COUNTIFS(Clean_Data!$K$2:$K$289,$A10,Clean_Data!$W$2:$W$289,"Yes")+COUNTIFS(Clean_Data!$K$2:$K$289,$A10,Clean_Data!$W$2:$W$289,"Maybe")+COUNTIFS(Clean_Data!$K$2:$K$289,$A10,Clean_Data!$W$2:$W$289,"No")),"") -> 0.54545455 | H10: =IFERROR(AVERAGEIFS(Clean_Data!$U$2:$U$289,Clean_Data!$K$2:$K$289,$A10),"") -> 5.6363636
A11: Grammarly | B11: =COUNTIFS(Clean_Data!$K$2:$K$289,$A11) -> 14 | C11: =B11/SUM(B$6:B$13) -> 0.050359712 | D11: =IFERROR(AVERAGEIFS(Clean_Data!$T$2:$T$289,Clean_Data!$K$2:$K$289,$A11),"") -> 6.2857143 | E11: =IFERROR(AVERAGEIFS(Clean_Data!$R$2:$R$289,Clean_Data!$K$2:$K$289,$A11),"") -> 5.1142857 | F11: =IFERROR(AVERAGEIFS(Clean_Data!$S$2:$S$289,Clean_Data!$K$2:$K$289,$A11),"") -> 3.8571429 | G11: =IFERROR(COUNTIFS(Clean_Data!$K$2:$K$289,$A11,Clean_Data!$W$2:$W$289,"Yes")/(COUNTIFS(Clean_Data!$K$2:$K$289,$A11,Clean_Data!$W$2:$W$289,"Yes")+COUNTIFS(Clean_Data!$K$2:$K$289,$A11,Clean_Data!$W$2:$W$289,"Maybe")+COUNTIFS(Clean_Data!$K$2:$K$289,$A11,Clean_Data!$W$2:$W$289,"No")),"") -> 0.64285714 | H11: =IFERROR(AVERAGEIFS(Clean_Data!$U$2:$U$289,Clean_Data!$K$2:$K$289,$A11),"") -> 5.4857143
A12: Meta AI | B12: =COUNTIFS(Clean_Data!$K$2:$K$289,$A12) -> 10 | C12: =B12/SUM(B$6:B$13) -> 0.035971223 | D12: =IFERROR(AVERAGEIFS(Clean_Data!$T$2:$T$289,Clean_Data!$K$2:$K$289,$A12),"") -> 6.1 | E12: =IFERROR(AVERAGEIFS(Clean_Data!$R$2:$R$289,Clean_Data!$K$2:$K$289,$A12),"") -> 5.15 | F12: =IFERROR(AVERAGEIFS(Clean_Data!$S$2:$S$289,Clean_Data!$K$2:$K$289,$A12),"") -> 3.5 | G12: =IFERROR(COUNTIFS(Clean_Data!$K$2:$K$289,$A12,Clean_Data!$W$2:$W$289,"Yes")/(COUNTIFS(Clean_Data!$K$2:$K$289,$A12,Clean_Data!$W$2:$W$289,"Yes")+COUNTIFS(Clean_Data!$K$2:$K$289,$A12,Clean_Data!$W$2:$W$289,"Maybe")+COUNTIFS(Clean_Data!$K$2:$K$289,$A12,Clean_Data!$W$2:$W$289,"No")),"") -> 0.4 | H12: =IFERROR(AVERAGEIFS(Clean_Data!$U$2:$U$289,Clean_Data!$K$2:$K$289,$A12),"") -> 4.79
A13: DeepSeek | B13: =COUNTIFS(Clean_Data!$K$2:$K$289,$A13) -> 9 | C13: =B13/SUM(B$6:B$13) -> 0.032374101 | D13: =IFERROR(AVERAGEIFS(Clean_Data!$T$2:$T$289,Clean_Data!$K$2:$K$289,$A13),"") -> 6.125 | E13: =IFERROR(AVERAGEIFS(Clean_Data!$R$2:$R$289,Clean_Data!$K$2:$K$289,$A13),"") -> 5.5333333 | F13: =IFERROR(AVERAGEIFS(Clean_Data!$S$2:$S$289,Clean_Data!$K$2:$K$289,$A13),"") -> 3.75 | G13: =IFERROR(COUNTIFS(Clean_Data!$K$2:$K$289,$A13,Clean_Data!$W$2:$W$289,"Yes")/(COUNTIFS(Clean_Data!$K$2:$K$289,$A13,Clean_Data!$W$2:$W$289,"Yes")+COUNTIFS(Clean_Data!$K$2:$K$289,$A13,Clean_Data!$W$2:$W$289,"Maybe")+COUNTIFS(Clean_Data!$K$2:$K$289,$A13,Clean_Data!$W$2:$W$289,"No")),"") -> 0.625 | H13: =IFERROR(AVERAGEIFS(Clean_Data!$U$2:$U$289,Clean_Data!$K$2:$K$289,$A13),"") -> 6.5571429
A16: 2. What people use AI for
A17: AI Purpose | B17: Users | C17: Students | D17: Professionals | E17: Avg Productivity (1-10) | F17: Avg Hrs Saved / Week
A18: Coding | B18: =COUNTIFS(Clean_Data!$L$2:$L$289,$A18) -> 65 | C18: =COUNTIFS(Clean_Data!$L$2:$L$289,$A18,Clean_Data!$F$2:$F$289,"Student") -> 28 | D18: =COUNTIFS(Clean_Data!$L$2:$L$289,$A18,Clean_Data!$F$2:$F$289,"Professional") -> 37 | E18: =IFERROR(AVERAGEIFS(Clean_Data!$R$2:$R$289,Clean_Data!$L$2:$L$289,$A18),"") -> 4.9444444 | F18: =IFERROR(AVERAGEIFS(Clean_Data!$U$2:$U$289,Clean_Data!$L$2:$L$289,$A18),"") -> 5.625
A19: Writing | B19: =COUNTIFS(Clean_Data!$L$2:$L$289,$A19) -> 49 | C19: =COUNTIFS(Clean_Data!$L$2:$L$289,$A19,Clean_Data!$F$2:$F$289,"Student") -> 29 | D19: =COUNTIFS(Clean_Data!$L$2:$L$289,$A19,Clean_Data!$F$2:$F$289,"Professional") -> 20 | E19: =IFERROR(AVERAGEIFS(Clean_Data!$R$2:$R$289,Clean_Data!$L$2:$L$289,$A19),"") -> 5.5425532 | F19: =IFERROR(AVERAGEIFS(Clean_Data!$U$2:$U$289,Clean_Data!$L$2:$L$289,$A19),"") -> 7.0234043
A20: Studying | B20: =COUNTIFS(Clean_Data!$L$2:$L$289,$A20) -> 39 | C20: =COUNTIFS(Clean_Data!$L$2:$L$289,$A20,Clean_Data!$F$2:$F$289,"Student") -> 39 | D20: =COUNTIFS(Clean_Data!$L$2:$L$289,$A20,Clean_Data!$F$2:$F$289,"Professional") -> 0 | E20: =IFERROR(AVERAGEIFS(Clean_Data!$R$2:$R$289,Clean_Data!$L$2:$L$289,$A20),"") -> 5.0447368 | F20: =IFERROR(AVERAGEIFS(Clean_Data!$U$2:$U$289,Clean_Data!$L$2:$L$289,$A20),"") -> 5.2461538
A21: Research | B21: =COUNTIFS(Clean_Data!$L$2:$L$289,$A21) -> 38 | C21: =COUNTIFS(Clean_Data!$L$2:$L$289,$A21,Clean_Data!$F$2:$F$289,"Student") -> 27 | D21: =COUNTIFS(Clean_Data!$L$2:$L$289,$A21,Clean_Data!$F$2:$F$289,"Professional") -> 11 | E21: =IFERROR(AVERAGEIFS(Clean_Data!$R$2:$R$289,Clean_Data!$L$2:$L$289,$A21),"") -> 5.3514286 | F21: =IFERROR(AVERAGEIFS(Clean_Data!$U$2:$U$289,Clean_Data!$L$2:$L$289,$A21),"") -> 6.2973684
A22: Content Creation | B22: =COUNTIFS(Clean_Data!$L$2:$L$289,$A22) -> 28 | C22: =COUNTIFS(Clean_Data!$L$2:$L$289,$A22,Clean_Data!$F$2:$F$289,"Student") -> 13 | D22: =COUNTIFS(Clean_Data!$L$2:$L$289,$A22,Clean_Data!$F$2:$F$289,"Professional") -> 15 | E22: =IFERROR(AVERAGEIFS(Clean_Data!$R$2:$R$289,Clean_Data!$L$2:$L$289,$A22),"") -> 5.1 | F22: =IFERROR(AVERAGEIFS(Clean_Data!$U$2:$U$289,Clean_Data!$L$2:$L$289,$A22),"") -> 5.4464286
A23: Data Analysis | B23: =COUNTIFS(Clean_Data!$L$2:$L$289,$A23) -> 25 | C23: =COUNTIFS(Clean_Data!$L$2:$L$289,$A23,Clean_Data!$F$2:$F$289,"Student") -> 7 | D23: =COUNTIFS(Clean_Data!$L$2:$L$289,$A23,Clean_Data!$F$2:$F$289,"Professional") -> 18 | E23: =IFERROR(AVERAGEIFS(Clean_Data!$R$2:$R$289,Clean_Data!$L$2:$L$289,$A23),"") -> 5.3954545 | F23: =IFERROR(AVERAGEIFS(Clean_Data!$U$2:$U$289,Clean_Data!$L$2:$L$289,$A23),"") -> 5.1916667
A24: Customer Support | B24: =COUNTIFS(Clean_Data!$L$2:$L$289,$A24) -> 20 | C24: =COUNTIFS(Clean_Data!$L$2:$L$289,$A24,Clean_Data!$F$2:$F$289,"Student") -> 0 | D24: =COUNTIFS(Clean_Data!$L$2:$L$289,$A24,Clean_Data!$F$2:$F$289,"Professional") -> 20 | E24: =IFERROR(AVERAGEIFS(Clean_Data!$R$2:$R$289,Clean_Data!$L$2:$L$289,$A24),"") -> 5.56 | F24: =IFERROR(AVERAGEIFS(Clean_Data!$U$2:$U$289,Clean_Data!$L$2:$L$289,$A24),"") -> 4.8235294
A25: Office Work | B25: =COUNTIFS(Clean_Data!$L$2:$L$289,$A25) -> 11 | C25: =COUNTIFS(Clean_Data!$L$2:$L$289,$A25,Clean_Data!$F$2:$F$289,"Student") -> 0 | D25: =COUNTIFS(Clean_Data!$L$2:$L$289,$A25,Clean_Data!$F$2:$F$289,"Professional") -> 11 | E25: =IFERROR(AVERAGEIFS(Clean_Data!$R$2:$R$289,Clean_Data!$L$2:$L$289,$A25),"") -> 5.9454545 | F25: =IFERROR(AVERAGEIFS(Clean_Data!$U$2:$U$289,Clean_Data!$L$2:$L$289,$A25),"") -> 7.2555556
A28: 3. Students vs professionals
A29: Metric | B29: Student | C29: Professional | D29: All Users
A30: Users | B30: =COUNTIFS(Clean_Data!$F$2:$F$289,"Student") -> 151 | C30: =COUNTIFS(Clean_Data!$F$2:$F$289,"Professional") -> 137 | D30: =COUNTA(Clean_Data!$A$2:$A$289) -> 288
A31: Avg age | B31: =IFERROR(AVERAGEIFS(Clean_Data!$B$2:$B$289,Clean_Data!$F$2:$F$289,"Student"),"") -> 22.191176 | C31: =IFERROR(AVERAGEIFS(Clean_Data!$B$2:$B$289,Clean_Data!$F$2:$F$289,"Professional"),"") -> 37.566929 | D31: =IFERROR(AVERAGE(Clean_Data!$B$2:$B$289),"") -> 29.61597
A32: Avg monthly income | B32: =IFERROR(AVERAGEIFS(Clean_Data!$J$2:$J$289,Clean_Data!$F$2:$F$289,"Student"),"") -> 211.86986 | C32: =IFERROR(AVERAGEIFS(Clean_Data!$J$2:$J$289,Clean_Data!$F$2:$F$289,"Professional"),"") -> 2828.1603 | D32: =IFERROR(AVERAGE(Clean_Data!$J$2:$J$289),"") -> 1449.1769
A33: Avg AI hours / day | B33: =IFERROR(AVERAGEIFS(Clean_Data!$M$2:$M$289,Clean_Data!$F$2:$F$289,"Student"),"") -> 3.0068493 | C33: =IFERROR(AVERAGEIFS(Clean_Data!$M$2:$M$289,Clean_Data!$F$2:$F$289,"Professional"),"") -> 2.7208955 | D33: =IFERROR(AVERAGE(Clean_Data!$M$2:$M$289),"") -> 2.87
A34: Avg work/study hours / day | B34: =IFERROR(AVERAGEIFS(Clean_Data!$N$2:$N$289,Clean_Data!$F$2:$F$289,"Student"),"") -> 6.23125 | C34: =IFERROR(AVERAGEIFS(Clean_Data!$N$2:$N$289,Clean_Data!$F$2:$F$289,"Professional"),"") -> 8.3437037 | D34: =IFERROR(AVERAGE(Clean_Data!$N$2:$N$289),"") -> 7.253405
A35: Avg productivity (1-10) | B35: =IFERROR(AVERAGEIFS(Clean_Data!$R$2:$R$289,Clean_Data!$F$2:$F$289,"Student"),"") -> 5.1923077 | C35: =IFERROR(AVERAGEIFS(Clean_Data!$R$2:$R$289,Clean_Data!$F$2:$F$289,"Professional"),"") -> 5.2816794 | D35: =IFERROR(AVERAGE(Clean_Data!$R$2:$R$289),"") -> 5.2350365
A36: Avg accuracy (1-5) | B36: =IFERROR(AVERAGEIFS(Clean_Data!$S$2:$S$289,Clean_Data!$F$2:$F$289,"Student"),"") -> 3.3661972 | C36: =IFERROR(AVERAGEIFS(Clean_Data!$S$2:$S$289,Clean_Data!$F$2:$F$289,"Professional"),"") -> 3.469697 | D36: =IFERROR(AVERAGE(Clean_Data!$S$2:$S$289),"") -> 3.4160584
A37: Avg satisfaction (1-10) | B37: =IFERROR(AVERAGEIFS(Clean_Data!$T$2:$T$289,Clean_Data!$F$2:$F$289,"Student"),"") -> 6.1866667 | C37: =IFERROR(AVERAGEIFS(Clean_Data!$T$2:$T$289,Clean_Data!$F$2:$F$289,"Professional"),"") -> 6.0687023 | D37: =IFERROR(AVERAGE(Clean_Data!$T$2:$T$289),"") -> 6.1316726
A38: Avg hrs saved / week | B38: =IFERROR(AVERAGEIFS(Clean_Data!$U$2:$U$289,Clean_Data!$F$2:$F$289,"Student"),"") -> 6.0351351 | C38: =IFERROR(AVERAGEIFS(Clean_Data!$U$2:$U$289,Clean_Data!$F$2:$F$289,"Professional"),"") -> 5.5538462 | D38: =IFERROR(AVERAGE(Clean_Data!$U$2:$U$289),"") -> 5.8100719
A39: % on a paid plan | B39: =IFERROR(COUNTIFS(Clean_Data!$Q$2:$Q$289,"Paid",Clean_Data!$F$2:$F$289,"Student")/(COUNTIFS(Clean_Data!$Q$2:$Q$289,"Paid",Clean_Data!$F$2:$F$289,"Student")+COUNTIFS(Clean_Data!$Q$2:$Q$289,"Free",Clean_Data!$F$2:$F$289,"Student")),"") -> 0.47651007 | C39: =IFERROR(COUNTIFS(Clean_Data!$Q$2:$Q$289,"Paid",Clean_Data!$F$2:$F$289,"Professional")/(COUNTIFS(Clean_Data!$Q$2:$Q$289,"Paid",Clean_Data!$F$2:$F$289,"Professional")+COUNTIFS(Clean_Data!$Q$2:$Q$289,"Free",Clean_Data!$F$2:$F$289,"Professional")),"") -> 0.45669291 | D39: =IFERROR(COUNTIFS(Clean_Data!$Q$2:$Q$289,"Paid")/(COUNTIFS(Clean_Data!$Q$2:$Q$289,"Paid")+COUNTIFS(Clean_Data!$Q$2:$Q$289,"Free")),"") -> 0.4673913
A40: % would recommend (Yes) | B40: =IFERROR(COUNTIFS(Clean_Data!$W$2:$W$289,"Yes",Clean_Data!$F$2:$F$289,"Student")/(COUNTIFS(Clean_Data!$W$2:$W$289,"Yes",Clean_Data!$F$2:$F$289,"Student")+COUNTIFS(Clean_Data!$W$2:$W$289,"Maybe",Clean_Data!$F$2:$F$289,"Student")+COUNTIFS(Clean_Data!$W$2:$W$289,"No",Clean_Data!$F$2:$F$289,"Student")),"") -> 0.61073826 | C40: =IFERROR(COUNTIFS(Clean_Data!$W$2:$W$289,"Yes",Clean_Data!$F$2:$F$289,"Professional")/(COUNTIFS(Clean_Data!$W$2:$W$289,"Yes",Clean_Data!$F$2:$F$289,"Professional")+COUNTIFS(Clean_Data!$W$2:$W$289,"Maybe",Clean_Data!$F$2:$F$289,"Professional")+COUNTIFS(Clean_Data!$W$2:$W$289,"No",Clean_Data!$F$2:$F$289,"Professional")),"") -> 0.58955224 | D40: =IFERROR(COUNTIFS(Clean_Data!$W$2:$W$289,"Yes")/(COUNTIFS(Clean_Data!$W$2:$W$289,"Yes")+COUNTIFS(Clean_Data!$W$2:$W$289,"Maybe")+COUNTIFS(Clean_Data!$W$2:$W$289,"No")),"") -> 0.60070671
A43: 4. Top 10 countries by number of users
A44: Country | B44: Users | C44: Avg Satisfaction (1-10) | D44: Avg Hrs Saved / Week
A45: India | B45: =COUNTIFS(Clean_Data!$E$2:$E$289,$A45) -> 43 | C45: =IFERROR(AVERAGEIFS(Clean_Data!$T$2:$T$289,Clean_Data!$E$2:$E$289,$A45),"") -> 6.3571429 | D45: =IFERROR(AVERAGEIFS(Clean_Data!$U$2:$U$289,Clean_Data!$E$2:$E$289,$A45),"") -> 5.2547619
A46: United States | B46: =COUNTIFS(Clean_Data!$E$2:$E$289,$A46) -> 34 | C46: =IFERROR(AVERAGEIFS(Clean_Data!$T$2:$T$289,Clean_Data!$E$2:$E$289,$A46),"") -> 6.0588235 | D46: =IFERROR(AVERAGEIFS(Clean_Data!$U$2:$U$289,Clean_Data!$E$2:$E$289,$A46),"") -> 6.4125
A47: Canada | B47: =COUNTIFS(Clean_Data!$E$2:$E$289,$A47) -> 31 | C47: =IFERROR(AVERAGEIFS(Clean_Data!$T$2:$T$289,Clean_Data!$E$2:$E$289,$A47),"") -> 6.3225806 | D47: =IFERROR(AVERAGEIFS(Clean_Data!$U$2:$U$289,Clean_Data!$E$2:$E$289,$A47),"") -> 6.4933333
...

Sheet Clean_Data
A1: User_ID | B1: Age | C1: Age_Group | D1: Gender | E1: Country | F1: User_Type | G1: Education_Level | H1: Profession | I1: Profession_Group | J1: Monthly_Income | K1: AI_Tool | L1: AI_Purpose | M1: AI_Hours_Per_Day | N1: Work_Study_Hours_Per_Day | O1: AI_Share_of_Day | P1: Monthly_AI_Cost | Q1: Plan_Type | R1: Productivity_Score | S1: Accuracy_Rating | T1: Satisfaction_Score | U1: Time_Saved_Hours_Per_Week | V1: Hours_Saved_per_AI_Hour | W1: Would_Recommend | X1: Data_Flags | Y1: Tasks_Performed
A2: U0269 | B2: 30 | C2: =IF(B2="","",IF(B2<18,"Under 18",IF(B2<25,"18-24",IF(B2<35,"25-34",IF(B2<45,"35-44","45+"))))) -> 25-34 | D2: Male | E2: United Kingdom | F2: Professional | G2: Master's | H2: Business Analyst | I2: Data & Analytics | J2: 5421 | K2: ChatGPT | L2: Office Work | M2: 2 | N2: 7.3 | O2: =IF(OR(M2="",N2=""),"",M2/N2) -> 0.2739726 | Q2: =IF(P2="","",IF(P2=0,"Free","Paid")) | R2: 5.3 | S2: 4 | T2: 7 | U2: 3.9 | V2: =IF(OR(U2="",M2="",M2=0),"",U2/(M2*7)) -> 0.27857143 | W2: Yes | Y2: Data analysis using AI-powered analytics tools, automated report generation, process optimization modelling, AI-assisted business intelligence reporting
A3: U0217 | B3: 30 | C3: =IF(B3="","",IF(B3<18,"Under 18",IF(B3<25,"18-24",IF(B3<35,"25-34",IF(B3<45,"35-44","45+"))))) -> 25-34 | D3: Male | E3: United States | F3: Professional | G3: Bachelor's | H3: Customer Support Specialist | I3: Customer Support | J3: 8903 | K3: ChatGPT | L3: Customer Support | M3: 5.7 | N3: 8.4 | O3: =IF(OR(M3="",N3=""),"",M3/N3) -> 0.67857143 | P3: 0 | Q3: =IF(P3="","",IF(P3=0,"Free","Paid")) -> Free | R3: 9.9 | S3: 3 | T3: 9 | U3: 11.4 | V3: =IF(OR(U3="",M3="",M3=0),"",U3/(M3*7)) -> 0.28571429 | W3: Yes | Y3: Resolving customer inquiries using AI chatbot platforms, drafting personalized email responses with AI writing assistants, analyzing customer sentiment with AI tools, managing support tickets with AI-powered ticketing systems
A4: U0152 | B4: 17 | C4: =IF(B4="","",IF(B4<18,"Under 18",IF(B4<25,"18-24",IF(B4<35,"25-34",IF(B4<45,"35-44","45+"))))) -> Under 18 | D4: Male | E4: Canada | F4: Student | H4: Computer Science Student | I4: Software & IT | J4: 402 | K4: ChatGPT | L4: Coding | M4: 1 | N4: 6.7 | O4: =IF(OR(M4="",N4=""),"",M4/N4) -> 0.14925373 | P4: 20 | Q4: =IF(P4="","",IF(P4=0,"Free","Paid")) -> Paid | R4: 3.2 | S4: 2 | T4: 4 | U4: 5.2 | V4: =IF(OR(U4="",M4="",M4=0),"",U4/(M4*7)) -> 0.74285714 | W4: No
A5: U0264 | B5: 35 | C5: =IF(B5="","",IF(B5<18,"Under 18",IF(B5<25,"18-24",IF(B5<35,"25-34",IF(B5<45,"35-44","45+"))))) -> 35-44 | D5: Female | E5: Brazil | F5: Professional | G5: Bachelor's | H5: Desenvolvedora de Software / Software Developer | I5: Software & IT | J5: 1367 | K5: Meta AI | L5: Coding | M5: 1.7 | N5: 9.6 | O5: =IF(OR(M5="",N5=""),"",M5/N5) -> 0.17708333 | P5: 20 | Q5: =IF(P5="","",IF(P5=0,"Free","Paid")) -> Paid | R5: 5.6 | S5: 4 | T5: 5 | U5: 6.4 | V5: =IF(OR(U5="",M5="",M5=0),"",U5/(M5*7)) -> 0.53781513 | W5: Maybe | Y5: Usar GitHub Copilot para autocompletar código, debugar aplicações com assistência de IA, otimizar algoritmos com sugestões de IA, revisar e refatorar código existente
A6: U0263 | B6: 19 | C6: =IF(B6="","",IF(B6<18,"Under 18",IF(B6<25,"18-24",IF(B6<35,"25-34",IF(B6<45,"35-44","45+"))))) -> 18-24 | D6: Female | E6: Canada | F6: Student | G6: Undergraduate | H6: Biology Student | I6: Science & Research | J6: 438 | K6: Perplexity AI | M6: 4.1 | N6: 6.2 | O6: =IF(OR(M6="",N6=""),"",M6/N6) -> 0.66129032 | P6: 0 | Q6: =IF(P6="","",IF(P6=0,"Free","Paid")) -> Free | R6: 4.7 | S6: 4 | T6: 7 | U6: 9.2 | V6: =IF(OR(U6="",M6="",M6=0),"",U6/(M6*7)) -> 0.32055749 | W6: Yes | Y6: Using AI to generate study summaries for exam preparation, getting help with practice problem solutions, organizing research paper notes
A7: U0225 | B7: 19 | C7: =IF(B7="","",IF(B7<18,"Under 18",IF(B7<25,"18-24",IF(B7<35,"25-34",IF(B7<45,"35-44","45+"))))) -> 18-24 | E7: United States | F7: Student | G7: Undergraduate | H7: Business Analytics Student | I7: Data & Analytics | J7: 774 | K7: Meta AI | L7: Data Analysis | M7: 1.5 | N7: 7.4 | O7: =IF(OR(M7="",N7=""),"",M7/N7) -> 0.2027027 | P7: 0 | Q7: =IF(P7="","",IF(P7=0,"Free","Paid")) -> Free | R7: 5 | S7: 3 | T7: 6 | U7: 2.9 | V7: =IF(OR(U7="",M7="",M7=0),"",U7/(M7*7)) -> 0.27619048 | W7: No | Y7: Statistical analysis on datasets, data visualization with Python libraries, predictive modeling for coursework, business intelligence report generation
A8: U0246 | B8: 32 | C8: =IF(B8="","",IF(B8<18,"Under 18",IF(B8<25,"18-24",IF(B8<35,"25-34",IF(B8<45,"35-44","45+"))))) -> 25-34 | D8: Male | E8: France | F8: Professional | G8: Bachelor's | H8: Développeur Full Stack | I8: Software & IT | J8: 4466 | K8: ChatGPT | L8: Coding | M8: 1.2 | N8: 6.4 | O8: =IF(OR(M8="",N8=""),"",M8/N8) -> 0.1875 | P8: 20 | Q8: =IF(P8="","",IF(P8=0,"Free","Paid")) -> Paid | R8: 3 | S8: 2 | T8: 5 | U8: 6.6 | V8: =IF(OR(U8="",M8="",M8=0),"",U8/(M8*7)) -> 0.78571429 | W8: Yes | Y8: Automated code review with AI-powered linters, Generated boilerplate code and API endpoints using GitHub Copilot, Debugged complex algorithms with AI assistance, Optimized database queries using AI suggestions
A9: U0177 | B9: 32 | C9: =IF(B9="","",IF(B9<18,"Under 18",IF(B9<25,"18-24",IF(B9<35,"25-34",IF(B9<45,"35-44","45+"))))) -> 25-34 | D9: Male | E9: Philippines | F9: Professional | G9: High School | H9: Social Media Content Creator | I9: Content, Media & Writing | J9: 486 | K9: ChatGPT | L9: Content Creation | M9: 2 | N9: 6.4 | O9: =IF(OR(M9="",N9=""),"",M9/N9) -> 0.3125 | P9: 0 | Q9: =IF(P9="","",IF(P9=0,"Free","Paid")) -> Free | R9: 6.5 | S9: 2 | T9: 5 | U9: 3.2 | V9: =IF(OR(U9="",M9="",M9=0),"",U9/(M9*7)) -> 0.22857143 | W9: Yes | Y9: Creating Instagram/TikTok captions with AI writing tools, Generating YouTube thumbnails and video descriptions using AI design assistants, Editing photos and videos with AI-powered software
A10: U0207 | B10: 16 | C10: =IF(B10="","",IF(B10<18,"Under 18",IF(B10<25,"18-24",IF(B10<35,"25-34",IF(B10<45,"35-44","45+"))))) -> Under 18 | D10: Male | E10: Philippines | F10: Student | G10: Undergraduate | H10: Digital Media Production Student | I10: Content, Media & Writing | J10: 132 | K10: Claude | L10: Content Creation | M10: 1.6 | N10: 3.8 | O10: =IF(OR(M10="",N10=""),"",M10/N10) -> 0.42105263 | P10: 30 | Q10: =IF(P10="","",IF(P10=0,"Free","Paid")) -> Paid | R10: 4.7 | S10: 4 | T10: 6 | U10: 3.8 | V10: =IF(OR(U10="",M10="",M10=0),"",U10/(M10*7)) -> 0.33928571 | W10: Yes | Y10: Creating YouTube video scripts, Designing social media graphics with AI image generators, Writing blog content for tech topics
A11: U0167 | B11: 40 | C11: =IF(B11="","",IF(B11<18,"Under 18",IF(B11<25,"18-24",IF(B11<35,"25-34",IF(B11<45,"35-44","45+"))))) -> 35-44 | D11: Male | E11: India | F11: Professional | G11: High School | J11: 1595 | K11: ChatGPT | L11: Writing | M11: 1.7 | N11: 9.4 | O11: =IF(OR(M11="",N11=""),"",M11/N11) -> 0.18085106 | P11: 10 | Q11: =IF(P11="","",IF(P11=0,"Free","Paid")) -> Paid | S11: 2 | T11: 5 | U11: 7.5 | V11: =IF(OR(U11="",M11="",M11=0),"",U11/(M11*7)) -> 0.6302521 | W11: Maybe | Y11: Email copywriting, Social media post creation, Blog article drafting, Product description writing
A12: U0135 | B12: 36 | C12: =IF(B12="","",IF(B12<18,"Under 18",IF(B12<25,"18-24",IF(B12<35,"25-34",IF(B12<45,"35-44","45+"))))) -> 35-44 | D12: Female | E12: Pakistan | F12: Professional | G12: Master's | H12: Research Analyst | I12: Data & Analytics | J12: 856 | K12: ChatGPT | L12: Research | M12: 2.7 | N12: 8.7 | O12: =IF(OR(M12="",N12=""),"",M12/N12) -> 0.31034483 | P12: 0 | Q12: =IF(P12="","",IF(P12=0,"Free","Paid")) -> Free | S12: 4 | T12: 6 | U12: 5.7 | V12: =IF(OR(U12="",M12="",M12=0),"",U12/(M12*7)) -> 0.3015873 | W12: Yes | Y12: Literature review and synthesis using AI-powered databases, Data analysis and pattern recognition, Research paper writing and academic content generation
A13: U0211 | B13: 22 | C13: =IF(B13="","",IF(B13<18,"Under 18",IF(B13<25,"18-24",IF(B13<35,"25-34",IF(B13<45,"35-44","45+"))))) -> 18-24 | D13: Male | E13: Canada | F13: Student | G13: Undergraduate | H13: Mechanical Engineering Student | I13: Engineering | J13: 547 | K13: Claude | L13: Research | M13: 5 | N13: 5.6 | O13: =IF(OR(M13="",N13=""),"",M13/N13) -> 0.89285714 | P13: 0 | Q13: =IF(P13="","",IF(P13=0,"Free","Paid")) -> Free | R13: 6.6 | S13: 3 | T13: 6 | U13: 9.8 | V13: =IF(OR(U13="",M13="",M13=0),"",U13/(M13*7)) -> 0.28 | W13: No | Y13: Literature review and paper summarization, Data analysis for lab experiments, Generating research hypotheses, Technical documentation and report writing
A14: U0114 | B14: 30 | C14: =IF(B14="","",IF(B14<18,"Under 18",IF(B14<25,"18-24",IF(B14<35,"25-34",IF(B14<45,"35-44","45+"))))) -> 25-34 | D14: Female | E14: Australia | F14: Professional | G14: Bachelor's | H14: Software Developer | I14: Software & IT | J14: 3307 | K14: ChatGPT | L14: Coding | M14: 0.8 | N14: 8 | O14: =IF(OR(M14="",N14=""),"",M14/N14) -> 0.1 | P14: 10 | Q14: =IF(P14="","",IF(P14=0,"Free","Paid")) -> Paid | R14: 2.3 | S14: 4 | T14: 4 | U14: 0.5 | V14: =IF(OR(U14="",M14="",M14=0),"",U14/(M14*7)) -> 0.089285714 | W14: No | Y14: Using AI code completion tools for writing Python functions, debugging code with AI-assisted analysis, generating unit test cases with AI tools
A15: U0191 | B15: 21 | C15: =IF(B15="","",IF(B15<18,"Under 18",IF(B15<25,"18-24",IF(B15<35,"25-34",IF(B15<45,"35-44","45+"))))) -> 18-24 | D15: Female | E15: Canada | F15: Student | G15: Undergraduate | H15: Software Engineering Student | I15: Software & IT | J15: 387 | K15: ChatGPT | L15: Coding | M15: 5.8 | N15: 4.8 | O15: =IF(OR(M15="",N15=""),"",M15/N15) -> 1.2083333 | P15: 30 | Q15: =IF(P15="","",IF(P15=0,"Free","Paid")) -> Paid | R15: 6.9 | S15: 4 | T15: 8 | U15: 10.2 | V15: =IF(OR(U15="",M15="",M15=0),"",U15/(M15*7)) -> 0.25123153 | W15: Yes | X15: AI hrs exceed work/study hrs (kept) | Y15: Debugging code with AI assistance, generating code snippets for assignments, learning programming concepts through AI explanations
A16: U0035 | B16: 28 | C16: =IF(B16="","",IF(B16<18,"Under 18",IF(B16<25,"18-24",IF(B16<35,"25-34",IF(B16<45,"35-44","45+"))))) -> 25-34 | D16: Male | E16: United Kingdom | F16: Professional | G16: Bachelor's | H16: Data Analyst | I16: Data & Analytics | J16: 3117 | K16: Claude | L16: Data Analysis | M16: 3.9 | N16: 7.6 | O16: =IF(OR(M16="",N16=""),"",M16/N16) -> 0.51315789 | P16: 10 | Q16: =IF(P16="","",IF(P16=0,"Free","Paid")) -> Paid | R16: 8.6 | S16: 3 | T16: 8 | U16: 11.8 | V16: =IF(OR(U16="",M16="",M16=0),"",U16/(M16*7)) -> 0.43223443 | W16: Yes | Y16: Automated data cleaning and processing with Python scripts, building predictive models using machine learning algorithms, generating interactive dashboards and visualizations in Power BI
A17: U0138 | B17: 16 | C17: =IF(B17="","",IF(B17<18,"Under 18",IF(B17<25,"18-24",IF(B17<35,"25-34",IF(B17<45,"35-44","45+"))))) -> Under 18 | D17: Female | E17: Canada | F17: Student | G17: Master's | J17: 324 | K17: Microsoft Copilot | L17: Coding | M17: 7.1 | N17: 3 | O17: =IF(OR(M17="",N17=""),"",M17/N17) -> 2.3666667 | P17: 20 | Q17: =IF(P17="","",IF(P17=0,"Free","Paid")) -> Paid | S17: 2 | T17: 5 | U17: 11.6 | V17: =IF(OR(U17="",M17="",M17=0),"",U17/(M17*7)) -> 0.2334004 | W17: No | X17: AI hrs exceed work/study hrs (kept)
A18: U0059 | B18: 22 | C18: =IF(B18="","",IF(B18<18,"Under 18",IF(B18<25,"18-24",IF(B18<35,"25-34",IF(B18<45,"35-44","45+"))))) -> 18-24 | D18: Male | E18: Canada | F18: Professional | G18: High School | H18: Customer Service Representative | I18: Customer Support | J18: 3546 | K18: Perplexity AI | L18: Customer Support | M18: 1.7 | N18: 6.7 | O18: =IF(OR(M18="",N18=""),"",M18/N18) -> 0.25373134 | P18: 0 | Q18: =IF(P18="","",IF(P18=0,"Free","Paid")) -> Free | R18: 7 | S18: 4 | T18: 7 | U18: 3.4 | V18: =IF(OR(U18="",M18="",M18=0),"",U18/(M18*7)) -> 0.28571429 | W18: Yes | Y18: Responding to customer inquiries via AI chatbots, drafting personalized support emails using AI writing assistants, resolving common technical issues with AI-guided troubleshooting scripts
A19: U0215 | B19: 23 | C19: =IF(B19="","",IF(B19<18,"Under 18",IF(B19<25,"18-24",IF(B19<35,"25-34",IF(B19<45,"35-44","45+"))))) -> 18-24 | D19: Male | E19: India | F19: Student | G19: Master's | H19: English Literature Student | I19: Content, Media & Writing | J19: 109 | K19: Google Gemini | L19: Writing | M19: 1.5 | N19: 3.9 | O19: =IF(OR(M19="",N19=""),"",M19/N19) -> 0.38461538 | P19: 20 | Q19: =IF(P19="","",IF(P19=0,"Free","Paid")) -> Paid | R19: 3.9 | S19: 3 | T19: 6 | U19: 3.7 | V19: =IF(OR(U19="",M19="",M19=0),"",U19/(M19*7)) -> 0.35238095 | W19: Yes | Y19: Drafting research papers on literary analysis, brainstorming essay outlines, proofreading and refining academic writing, generating content summaries for thesis work
A20: U0228 | B20: 22 | C20: =IF(B20="","",IF(B20<18,"Under 18",IF(B20<25,"18-24",IF(B20<35,"25-34",IF(B20<45,"35-44","45+"))))) -> 18-24 | D20: Male | E20: Kenya | F20: Student | G20: High School | H20: Biology Student | I20: Science & Research | J20: 109 | K20: ChatGPT | L20: Research | M20: 9.6 | N20: 5.2 | O20: =IF(OR(M20="",N20=""),"",M20/N20) -> 1.8461538 | P20: 20 | Q20: =IF(P20="","",IF(P20=0,"Free","Paid")) -> Paid | R20: 7.3 | S20: 4 | T20: 9 | U20: 19.4 | V20: =IF(OR(U20="",M20="",M20=0),"",U20/(M20*7)) -> 0.28869048 | W20: Yes | X20: AI hrs exceed work/study hrs (kept) | Y20: Literature review for lab reports, summarizing research papers on molecular genetics, generating study notes from scientific articles
A21: U0046 | B21: 61 | C21: =IF(B21="","",IF(B21<18,"Under 18",IF(B21<25,"18-24",IF(B21<35,"25-34",IF(B21<45,"35-44","45+"))))) -> 45+ | D21: Female | E21: Nigeria | F21: Professional | G21: Diploma | H21: Research Technician | I21: Science & Research | J21: 585 | K21: Google Gemini | L21: Research | N21: 9.5 | O21: =IF(OR(M21="",N21=""),"",M21/N21) | P21: 10 | Q21: =IF(P21="","",IF(P21=0,"Free","Paid")) -> Paid | R21: 4.1 | S21: 3 | T21: 4 | U21: 5.4 | V21: =IF(OR(U21="",M21="",M21=0),"",U21/(M21*7)) | W21: No | X21: AI hrs/day over 16, blanked | Y21: Literature review synthesis using AI search tools, Data analysis and statistical reporting with AI-assisted tools, Survey data organization and preliminary findings documentation
A22: U0176 | B22: 24 | C22: =IF(B22="","",IF(B22<18,"Under 18",IF(B22<25,"18-24",IF(B22<35,"25-34",IF(B22<45,"35-44","45+"))))) -> 18-24 | D22: Male | E22: India | F22: Professional | G22: Diploma | H22: AI-Powered Customer Support Executive | I22: Customer Support | J22: 1977 | K22: ChatGPT | L22: Customer Support | M22: 0.9 | N22: 7.3 | O22: =IF(OR(M22="",N22=""),"",M22/N22) -> 0.12328767 | P22: 10 | Q22: =IF(P22="","",IF(P22=0,"Free","Paid")) -> Paid | R22: 4.1 | S22: 3 | T22: 6 | U22: 0 | V22: =IF(OR(U22="",M22="",M22=0),"",U22/(M22*7)) -> 0 | W22: Maybe | Y22: AI chatbot management and customer query routing, multilingual customer response handling using AI tools, customer complaint analysis and resolution tracking
A23: U0227 | B23: 23 | C23: =IF(B23="","",IF(B23<18,"Under 18",IF(B23<25,"18-24",IF(B23<35,"25-34",IF(B23<45,"35-44","45+"))))) -> 18-24 | D23: Male | E23: Pakistan | F23: Student | G23: Master's | H23: English Literature Student | I23: Content, Media & Writing | J23: 0 | K23: ChatGPT | L23: Writing | M23: 1.7 | N23: 5.4 | O23: =IF(OR(M23="",N23=""),"",M23/N23) -> 0.31481481 | P23: 20 | Q23: =IF(P23="","",IF(P23=0,"Free","Paid")) -> Paid | R23: 2.8 | S23: 2 | T23: 3 | U23: 2.7 | V23: =IF(OR(U23="",M23="",M23=0),"",U23/(M23*7)) -> 0.22689076 | W23: No | Y23: Essay structuring and outline generation, thesis statement refinement, academic paper proofreading and grammar checking, creative writing brainstorming
A24: U0198 | B24: 29 | C24: =IF(B24="","",IF(B24<18,"Under 18",IF(B24<25,"18-24",IF(B24<35,"25-34",IF(B24<45,"35-44","45+"))))) -> 25-34 | D24: Female | E24: Germany | F24: Professional | G24: Bachelor's | H24: Kundenservice-Spezialistin / Customer Service Specialist | I24: Customer Support | K24: ChatGPT | L24: Customer Support | M24: 1 | N24: 8 | O24: =IF(OR(M24="",N24=""),"",M24/N24) -> 0.125 | Q24: =IF(P24="","",IF(P24=0,"Free","Paid")) | R24: 4 | S24: 3 | T24: 6 | U24: 2.7 | V24: =IF(OR(U24="",M24="",M24=0),"",U24/(M24*7)) -> 0.38571429 | W24: Maybe
A25: U0141 | B25: 29 | C25: =IF(B25="","",IF(B25<18,"Under 18",IF(B25<25,"18-24",IF(B25<35,"25-34",IF(B25<45,"35-44","45+"))))) -> 25-34 | E25: United Kingdom | F25: Student | G25: High School | H25: Computer Science Student | I25: Software & IT | J25: 0 | K25: Grammarly | L25: Coding | M25: 2.6 | N25: 6.2 | O25: =IF(OR(M25="",N25=""),"",M25/N25) -> 0.41935484 | P25: 10 | Q25: =IF(P25="","",IF(P25=0,"Free","Paid")) -> Paid | R25: 3.7 | S25: 4 | T25: 7 | U25: 4.8 | V25: =IF(OR(U25="",M25="",M25=0),"",U25/(M25*7)) -> 0.26373626 | W25: Yes | Y25: Debugging Python code with AI assistants, generating boilerplate code for web projects, learning algorithms through AI-generated explanations
A26: U0205 | B26: 24 | C26: =IF(B26="","",IF(B26<18,"Under 18",IF(B26<25,"18-24",IF(B26<35,"25-34",IF(B26<45,"35-44","45+"))))) -> 18-24 | D26: Male | E26: United Kingdom | F26: Student | H26: Mechanical Engineering Student | I26: Engineering | J26: 444 | K26: Google Gemini | L26: Studying | M26: 1.2 | N26: 7.2 | O26: =IF(OR(M26="",N26=""),"",M26/N26) -> 0.16666667 | P26: 0 | Q26: =IF(P26="","",IF(P26=0,"Free","Paid")) -> Free | R26: 3.8 | S26: 3 | T26: 5 | U26: 3 | V26: =IF(OR(U26="",M26="",M26=0),"",U26/(M26*7)) -> 0.35714286 | W26: No | Y26: Analyzing complex physics problems, generating study notes from lecture content, debugging code for coursework projects, creating visual explanations of thermodynamic concepts
A27: U0209 | B27: 28 | C27: =IF(B27="","",IF(B27<18,"Under 18",IF(B27<25,"18-24",IF(B27<35,"25-34",IF(B27<45,"35-44","45+"))))) -> 25-34 | D27: Female | E27: Philippines | F27: Professional | G27: Bachelor's | H27: Digital Content Creator | I27: Content, Media & Writing | J27: 392 | K27: ChatGPT | L27: Content Creation | M27: 1.6 | N27: 7.8 | O27: =IF(OR(M27="",N27=""),"",M27/N27) -> 0.20512821 | P27: 10 | Q27: =IF(P27="","",IF(P27=0,"Free","Paid")) -> Paid | R27: 4 | S27: 2 | T27: 3 | U27: 4.5 | V27: =IF(OR(U27="",M27="",M27=0),"",U27/(M27*7)) -> 0.40178571 | W27: Yes | Y27: Generating social media captions with AI, Creating blog post drafts using language models, Editing photos and videos with AI tools, Scheduling posts across multiple platforms
A28: U0149 | B28: 23 | C28: =IF(B28="","",IF(B28<18,"Under 18",IF(B28<25,"18-24",IF(B28<35,"25-34",IF(B28<45,"35-44","45+"))))) -> 18-24 | D28: Male | E28: Brazil | F28: Student | G28: Undergraduate | H28: Computer Science Student | I28: Software & IT | J28: 215 | K28: ChatGPT | L28: Coding | M28: 0.6 | N28: 6.5 | O28: =IF(OR(M28="",N28=""),"",M28/N28) -> 0.092307692 | P28: 10 | Q28: =IF(P28="","",IF(P28=0,"Free","Paid")) -> Paid | R28: 3 | S28: 4 | T28: 5 | U28: 0 | V28: =IF(OR(U28="",M28="",M28=0),"",U28/(M28*7)) -> 0 | W28: No | Y28: Writing and debugging Python code, generating documentation for projects, optimizing algorithms
A29: U0179 | B29: 28 | C29: =IF(B29="","",IF(B29<18,"Under 18",IF(B29<25,"18-24",IF(B29<35,"25-34",IF(B29<45,"35-44","45+"))))) -> 25-34 | D29: Male | E29: Brazil | F29: Professional | G29: Bachelor's | H29: Pesquisador de Mercado | I29: Science & Research | J29: 1567 | K29: Microsoft Copilot | L29: Research | M29: 0.7 | N29: 8.1 | O29: =IF(OR(M29="",N29=""),"",M29/N29) -> 0.086419753 | P29: 0 | Q29: =IF(P29="","",IF(P29=0,"Free","Paid")) -> Free | R29: 4 | S29: 3 | T29: 6 | U29: 4.4 | V29: =IF(OR(U29="",M29="",M29=0),"",U29/(M29*7)) -> 0.89795918 | W29: No | Y29: Análise de tendências usando ferramentas de IA, extração de dados de fontes públicas, geração de relatórios automatizados, síntese de artigos acadêmicos
A30: U0016 | B30: 23 | C30: =IF(B30="","",IF(B30<18,"Under 18",IF(B30<25,"18-24",IF(B30<35,"25-34",IF(B30<45,"35-44","45+"))))) -> 18-24 | D30: Female | E30: Canada | F30: Student | G30: Undergraduate | H30: Biology Student | I30: Science & Research | K30: ChatGPT | L30: Studying | M30: 7.4 | N30: 6.8 | O30: =IF(OR(M30="",N30=""),"",M30/N30) -> 1.0882353 | P30: 0 | Q30: =IF(P30="","",IF(P30=0,"Free","Paid")) -> Free | R30: 8.7 | S30: 3 | T30: 9 | U30: 12.3 | V30: =IF(OR(U30="",M30="",M30=0),"",U30/(M30*7)) -> 0.23745174 | W30: Yes | X30: AI hrs exceed work/study hrs (kept) | Y30: Using AI to generate practice exam questions, summarizing research papers, explaining complex concepts like cellular respiration
A31: U0132 | C31: =IF(B31="","",IF(B31<18,"Under 18",IF(B31<25,"18-24",IF(B31<35,"25-34",IF(B31<45,"35-44","45+"))))) | D31: Male | E31: Australia | F31: Student | H31: Business Administration Student | I31: Business & Admin | J31: 0 | K31: ChatGPT | L31: Research | M31: 5.4 | N31: 4.8 | O31: =IF(OR(M31="",N31=""),"",M31/N31) -> 1.125 | P31: 0 | Q31: =IF(P31="","",IF(P31=0,"Free","Paid")) -> Free | R31: 7.2 | S31: 4 | T31: 8 | U31: 10.7 | V31: =IF(OR(U31="",M31="",M31=0),"",U31/(M31*7)) -> 0.28306878 | W31: No | X31: AI hrs exceed work/study hrs (kept) | Y31: Literature review and source compilation, Data analysis and statistical interpretation, Essay research and citation management
A32: U0008 | B32: 23 | C32: =IF(B32="","",IF(B32<18,"Under 18",IF(B32<25,"18-24",IF(B32<35,"25-34",IF(B32<45,"35-44","45+"))))) -> 18-24 | D32: Male | E32: Australia | F32: Student | G32: Undergraduate | H32: English Literature Student | I32: Content, Media & Writing | J32: 531 | K32: ChatGPT | L32: Writing | M32: 5.2 | N32: 7 | O32: =IF(OR(M32="",N32=""),"",M32/N32) -> 0.74285714 | P32: 0 | Q32: =IF(P32="","",IF(P32=0,"Free","Paid")) -> Free | R32: 6.7 | T32: 7 | U32: 12.1 | V32: =IF(OR(U32="",M32="",M32=0),"",U32/(M32*7)) -> 0.33241758 | W32: Yes | Y32: Essay composition and structure planning, grammar checking and proofreading, research paper summarization, creative writing feedback and editing
A33: U0162 | B33: 44 | C33: =IF(B33="","",IF(B33<18,"Under 18",IF(B33<25,"18-24",IF(B33<35,"25-34",IF(B33<45,"35-44","45+"))))) -> 35-44 | D33: Female | E33: Kenya | F33: Professional | G33: Bachelor's | H33: Research Analyst | I33: Data & Analytics | J33: 258 | K33: DeepSeek | M33: 3.7 | N33: 6.9 | O33: =IF(OR(M33="",N33=""),"",M33/N33) -> 0.53623188 | P33: 0 | Q33: =IF(P33="","",IF(P33=0,"Free","Paid")) -> Free | R33: 4.6 | S33: 5 | T33: 6 | U33: 5.7 | V33: =IF(OR(U33="",M33="",M33=0),"",U33/(M33*7)) -> 0.22007722 | W33: Yes | Y33: Literature review automation using AI databases, conducting qualitative data analysis with AI tools, generating research reports and summaries, market research data collection and synthesis
A34: U0081 | B34: 23 | C34: =IF(B34="","",IF(B34<18,"Under 18",IF(B34<25,"18-24",IF(B34<35,"25-34",IF(B34<45,"35-44","45+"))))) -> 18-24 | D34: Male | E34: Nigeria | F34: Professional | G34: Diploma | H34: Research Assistant | I34: Science & Research | J34: 334 | K34: ChatGPT | L34: Research | M34: 2.3 | N34: 7.7 | O34: =IF(OR(M34="",N34=""),"",M34/N34) -> 0.2987013 | P34: 20 | Q34: =IF(P34="","",IF(P34=0,"Free","Paid")) -> Paid | R34: 3.9 | S34: 2 | T34: 5 | U34: 2.5 | V34: =IF(OR(U34="",M34="",M34=0),"",U34/(M34*7)) -> 0.1552795 | W34: No | Y34: Literature review using AI search tools, data analysis with AI-powered statistical software, market research report generation, academic paper summarization
A35: U0014 | B35: 23 | C35: =IF(B35="","",IF(B35<18,"Under 18",IF(B35<25,"18-24",IF(B35<35,"25-34",IF(B35<45,"35-44","45+"))))) -> 18-24 | D35: Male | E35: India | F35: Student | G35: High School | H35: Engineering Student | I35: Engineering | J35: 169 | L35: Studying | M35: 5.4 | N35: 6.9 | O35: =IF(OR(M35="",N35=""),"",M35/N35) -> 0.7826087 | P35: 0 | Q35: =IF(P35="","",IF(P35=0,"Free","Paid")) -> Free | R35: 8.1 | S35: 4 | T35: 9 | U35: 6.8 | V35: =IF(OR(U35="",M35="",M35=0),"",U35/(M35*7)) -> 0.17989418 | W35: Yes | Y35: Solving physics problems with AI explanation, generating practice questions for exams, translating complex concepts into simplified notes
A36: U0278 | B36: 22 | C36: =IF(B36="","",IF(B36<18,"Under 18",IF(B36<25,"18-24",IF(B36<35,"25-34",IF(B36<45,"35-44","45+"))))) -> 18-24 | D36: Male | E36: Canada | F36: Student | G36: Undergraduate | H36: Mechanical Engineering Student | I36: Engineering | J36: 507 | K36: Perplexity AI | L36: Studying | M36: 1.9 | N36: 4.1 | O36: =IF(OR(M36="",N36=""),"",M36/N36) -> 0.46341463 | P36: 0 | Q36: =IF(P36="","",IF(P36=0,"Free","Paid")) -> Free | R36: 4.6 | S36: 3 | T36: 4 | U36: 2 | V36: =IF(OR(U36="",M36="",M36=0),"",U36/(M36*7)) -> 0.15037594 | W36: Yes | Y36: Generating practice problems and solutions for thermodynamics assignments, debugging Python code for finite element analysis projects, summarizing lecture notes on fluid mechanics concepts
A37: U0102 | B37: 18 | C37: =IF(B37="","",IF(B37<18,"Under 18",IF(B37<25,"18-24",IF(B37<35,"25-34",IF(B37<45,"35-44","45+"))))) -> 18-24 | D37: Male | E37: Philippines | F37: Student | G37: Undergraduate | H37: Information Technology Student | I37: Software & IT | J37: 0 | K37: Google Gemini | L37: Studying | M37: 1.6 | N37: 3.2 | O37: =IF(OR(M37="",N37=""),"",M37/N37) -> 0.5 | P37: 0 | Q37: =IF(P37="","",IF(P37=0,"Free","Paid")) -> Free | R37: 3.3 | S37: 4 | T37: 5 | U37: 4.3 | V37: =IF(OR(U37="",M37="",M37=0),"",U37/(M37*7)) -> 0.38392857 | W37: Yes
A38: U0258 | B38: 16 | C38: =IF(B38="","",IF(B38<18,"Under 18",IF(B38<25,"18-24",IF(B38<35,"25-34",IF(B38<45,"35-44","45+"))))) -> Under 18 | D38: Female | F38: Student | G38: Undergraduate | J38: 63 | K38: Perplexity AI | L38: Research | M38: 1.9 | N38: 5.4 | O38: =IF(OR(M38="",N38=""),"",M38/N38) -> 0.35185185 | P38: 0 | Q38: =IF(P38="","",IF(P38=0,"Free","Paid")) -> Free | R38: 3.5 | S38: 3 | T38: 5 | U38: 3 | V38: =IF(OR(U38="",M38="",M38=0),"",U38/(M38*7)) -> 0.22556391 | W38: Maybe | Y38: Literature review and paper summarization, Data analysis and interpretation, Research proposal drafting, Scientific article finding and organization
A39: U0239 | B39: 45 | C39: =IF(B39="","",IF(B39<18,"Under 18",IF(B39<25,"18-24",IF(B39<35,"25-34",IF(B39<45,"35-44","45+"))))) -> 45+ | D39: Male | E39: Pakistan | F39: Professional | G39: Master's | H39: Senior Software Engineer | I39: Software & IT | J39: 887 | L39: Coding | M39: 1.5 | N39: 6.4 | O39: =IF(OR(M39="",N39=""),"",M39/N39) -> 0.234375 | P39: 0 | Q39: =IF(P39="","",IF(P39=0,"Free","Paid")) -> Free | R39: 5.3 | S39: 3 | T39: 5 | U39: 5.3 | V39: =IF(OR(U39="",M39="",M39=0),"",U39/(M39*7)) -> 0.5047619 | W39: Maybe | Y39: Code review and optimization using AI assistants, automated bug detection and debugging with AI tools, AI-assisted documentation generation, infrastructure code maintenance
A40: U0071 | B40: 30 | C40: =IF(B40="","",IF(B40<18,"Under 18",IF(B40<25,"18-24",IF(B40<35,"25-34",IF(B40<45,"35-44","45+"))))) -> 25-34 | E40: India | F40: Professional | G40: Master's | H40: Data Analytics Manager | I40: Data & Analytics | J40: 1699 | K40: Perplexity AI | L40: Data Analysis | M40: 5.5 | N40: 7.5 | O40: =IF(OR(M40="",N40=""),"",M40/N40) -> 0.73333333 | P40: 10 | Q40: =IF(P40="","",IF(P40=0,"Free","Paid")) -> Paid | S40: 4 | T40: 8 | U40: 6.5 | V40: =IF(OR(U40="",M40="",M40=0),"",U40/(M40*7)) -> 0.16883117 | W40: Yes | Y40: Building predictive models with Python and scikit-learn, Creating business intelligence dashboards in Tableau, Performing statistical analysis on customer datasets
...

Sheet Cleaning_Log
A1: Cleaning log
A2: What was wrong with the file, what was done about it, and how much of the data it touched.
A4: Rows in original file | B4: =COUNTA(Raw_Data!A:A)-1 -> 300
A5: Rows after removing duplicates | B5: =COUNTA(Clean_Data!A:A)-1 -> 288
A6: Columns in original file | B6: 19
A7: Columns in clean file (added 6) | B7: 25
A9: Step | B9: What was done | C9: Rows / cells affected
A10: Removed exact duplicate rows | B10: 12 rows were identical copies of another row (same User_ID and all fields) | C10: 12
A11: Converted Age to a number | B11: Stripped units/symbols such as "$", "hrs", "yrs" and thousands commas | C11: 12
A12: Converted Monthly_Income to a number | B12: Stripped units/symbols such as "$", "hrs", "yrs" and thousands commas | C12: 6
A13: Converted AI_Usage_Hours_Per_Day to a number | B13: Stripped units/symbols such as "$", "hrs", "yrs" and thousands commas | C13: 21
A14: Converted Work_or_Study_Hours_Per_Day to a number | B14: Stripped units/symbols such as "$", "hrs", "yrs" and thousands commas | C14: 12
A15: Converted Time_Saved_Hours_Per_Week to a number | B15: Stripped units/symbols such as "$", "hrs", "yrs" and thousands commas | C15: 15
A16: Converted Monthly_AI_Cost to a number | B16: Stripped units/symbols such as "$", "hrs", "yrs" and thousands commas | C16: 15
A17: Standardized Gender | B17: 11 spellings (male, MALE, M, F, FEMALE, Non-binary...) collapsed to Male, Female, Other / Non-binary | C17: 63
A18: Standardized Country | B18: Fixed casing (brazil -> Brazil) and merged U.K. and United States of America into the standard names | C18: 14
A19: Standardized Education_Level | B19: 16 variants reduced to 6 levels: High School, Diploma, Undergraduate, Bachelor's, Master's, PhD (Undergraduate = currently enrolled, kept separate from Bachelor's = completed) | C19: 16
A20: Standardized AI_Tool | B20: Merged ChatGPT / chatgpt / Chat GPT, Copilot / Microsoft Copilot, Gemini / Google Gemini, claude / Claude | C20: 16
A21: Blanked impossible Age | B21: Age above 90 is not credible for a working professional or a student (found 97 for a student) | C21: 2
... A27: Missing values | B27: Left blank, never guessed or averaged in. Every summary formula ignores blanks, so averages use only real answers. See the completeness table | C27: 215
A28: Counts above were measured in Python during cleaning and typed in here. They are a record of what happened, not live formulas.
A31: Completeness by column (clean file)
A32: Column | B32: Blank cells | C32: % filled
A33: User_ID | B33: =SUMPRODUCT(--(LEN(Clean_Data!$A$2:$A$289)=0)) -> 0 | C33: =1-B33/COUNTA(Clean_Data!$A$2:$A$289) -> 1
A34: Age | B34: =SUMPRODUCT(--(LEN(Clean_Data!$B$2:$B$289)=0)) -> 25 | C34: =1-B34/COUNTA(Clean_Data!$A$2:$A$289) -> 0.91319444
A35: Age_Group | B35: =SUMPRODUCT(--(LEN(Clean_Data!$C$2:$C$289)=0)) -> 25 | C35: =1-B35/COUNTA(Clean_Data!$A$2:$A$289) -> 0.91319444
A36: Gender | B36: =SUMPRODUCT(--(LEN(Clean_Data!$D$2:$D$289)=0)) -> 10 | C36: =1-B36/COUNTA(Clean_Data!$A$2:$A$289) -> 0.96527778
A37: Country | B37: =SUMPRODUCT(--(LEN(Clean_Data!$E$2:$E$289)=0)) -> 10 | C37: =1-B37/COUNTA(Clean_Data!$A$2:$A$289) -> 0.96527778
A38: User_Type | B38: =SUMPRODUCT(--(LEN(Clean_Data!$F$2:$F$289)=0)) -> 0 | C38: =1-B38/COUNTA(Clean_Data!$A$2:$A$289) -> 1
A39: Education_Level | B39: =SUMPRODUCT(--(LEN(Clean_Data!$G$2:$G$289)=0)) -> 12 | C39: =1-B39/COUNTA(Clean_Data!$A$2:$A$289) -> 0.95833333
A40: Profession | B40: =SUMPRODUCT(--(LEN(Clean_Data!$H$2:$H$289)=0)) -> 14 | C40: =1-B40/COUNTA(Clean_Data!$A$2:$A$289) -> 0.95138889
A41: Profession_Group | B41: =SUMPRODUCT(--(LEN(Clean_Data!$I$2:$I$289)=0)) -> 14 | C41: =1-B41/COUNTA(Clean_Data!$A$2:$A$289) -> 0.95138889
A42: Monthly_Income | B42: =SUMPRODUCT(--(LEN(Clean_Data!$J$2:$J$289)=0)) -> 11 | C42: =1-B42/COUNTA(Clean_Data!$A$2:$A$289) -> 0.96180556
A43: AI_Tool | B43: =SUMPRODUCT(--(LEN(Clean_Data!$K$2:$K$289)=0)) -> 10 | C43: =1-B43/COUNTA(Clean_Data!$A$2:$A$289) -> 0.96527778
A44: AI_Purpose | B44: =SUMPRODUCT(--(LEN(Clean_Data!$L$2:$L$289)=0)) -> 13 | C44: =1-B44/COUNTA(Clean_Data!$A$2:$A$289) -> 0.95486111
A45: AI_Hours_Per_Day | B45: =SUMPRODUCT(--(LEN(Clean_Data!$M$2:$M$289)=0)) -> 8 | C45: =1-B45/COUNTA(Clean_Data!$A$2:$A$289) -> 0.97222222
A46: Work_Study_Hours_Per_Day | B46: =SUMPRODUCT(--(LEN(Clean_Data!$N$2:$N$289)=0)) -> 9 | C46: =1-B46/COUNTA(Clean_Data!$A$2:$A$289) -> 0.96875
A47: AI_Share_of_Day | B47: =SUMPRODUCT(--(LEN(Clean_Data!$O$2:$O$289)=0)) -> 17 | C47: =1-B47/COUNTA(Clean_Data!$A$2:$A$289) -> 0.94097222
A48: Monthly_AI_Cost | B48: =SUMPRODUCT(--(LEN(Clean_Data!$P$2:$P$289)=0)) -> 12 | C48: =1-B48/COUNTA(Clean_Data!$A$2:$A$289) -> 0.95833333
A49: Plan_Type | B49: =SUMPRODUCT(--(LEN(Clean_Data!$Q$2:$Q$289)=0)) -> 12 | C49: =1-B49/COUNTA(Clean_Data!$A$2:$A$289) -> 0.95833333
...

Sheet Raw_Data
A1: User_ID | B1: Age | C1: Gender | D1: Country | E1: User_Type | F1: Education_Level | G1: Profession | H1: Monthly_Income | I1: AI_Tool | J1: AI_Purpose | K1: AI_Usage_Hours_Per_Day | L1: Tasks_Performed | M1: Monthly_AI_Cost | N1: Productivity_Score | O1: Accuracy_Rating | P1: Satisfaction_Score | Q1: Time_Saved_Hours_Per_Week | R1: Work_or_Study_Hours_Per_Day | S1: Would_Recommend
A2: U0269 | B2: 30 | C2: Male | D2: United Kingdom | E2: Professional | F2: Master's | G2: Business Analyst | H2: 5421 | I2: ChatGPT | J2: Office Work | K2: 2 hrs | L2: Data analysis using AI-powered analytics tools, automated report generation, process optimization modelling, AI-assisted business intelligence reporting | N2: 5.3 | O2: 4 | P2: 7 | Q2: 3.9 | R2: 7.3 | S2: Yes
A3: U0217 | B3: 30 | C3: Male | D3: United States | E3: Professional | F3: Bachelor's | G3: Customer Support Specialist | H3: 8903 | I3: ChatGPT | J3: Customer Support | K3: 5.7 | L3: Resolving customer inquiries using AI chatbot platforms, drafting personalized email responses with AI writing assistants, analyzing customer sentiment with AI tools, managing support tickets with AI-powered ticketing systems | M3: 0 | N3: 9.9 | O3: 3 | P3: 9 | Q3: 11.4 | R3: 8.4 hrs | S3: Yes
A4: U0152 | B4: 17 | C4: Male | D4: Canada | E4: Student | G4: Computer Science Student | H4: 402 | I4: Chat GPT | J4: Coding | K4: 1 hrs | M4: 20 | N4: 3.2 | O4: 2 | P4: 4 | Q4: 5.2 | R4: 6.7 | S4: No
A5: U0264 | B5: 35 | C5: FEMALE | D5: Brazil | E5: Professional | F5: Bachelor's | G5: Desenvolvedora de Software / Software Developer | H5: 1367 | I5: Meta AI | J5: Coding | K5: 1.7 | L5: Usar GitHub Copilot para autocompletar código, debugar aplicações com assistência de IA, otimizar algoritmos com sugestões de IA, revisar e refatorar código existente | M5: 20 | N5: 5.6 | O5: 4 | P5: 5 | Q5: 6.4 | R5: 9.6 | S5: Maybe
A6: U0263 | B6: 19 | C6: Female | D6: Canada | E6: Student | F6: Undergraduate | G6: Biology Student | H6: 438 | I6: Perplexity AI | K6: 4.1 | L6: Using AI to generate study summaries for exam preparation, getting help with practice problem solutions, organizing research paper notes | M6: 0 | N6: 4.7 | O6: 4 | P6: 7 | Q6: 9.2 | R6: 6.2 | S6: Yes
A7: U0225 | B7: 19 | D7: United States | E7: Student | F7: Undergraduate | G7: Business Analytics Student | H7: 774 | I7: Meta AI | J7: Data Analysis | K7: 1.5 | L7: Statistical analysis on datasets, data visualization with Python libraries, predictive modeling for coursework, business intelligence report generation | M7: 0 | N7: 5 | O7: 3 | P7: 6 | Q7: 2.9 | R7: 7.4 | S7: No
A8: U0246 | B8: 32 | C8: Male | D8: france | E8: Professional | F8: Bachelor's | G8: Développeur Full Stack | H8: 4466 | I8: ChatGPT | J8: Coding | K8: 1.2 | L8: Automated code review with AI-powered linters, Generated boilerplate code and API endpoints using GitHub Copilot, Debugged complex algorithms with AI assistance, Optimized database queries using AI suggestions | M8: 20 | N8: 3 | O8: 2 | P8: 5 | Q8: 6.6 | R8: 6.4 | S8: Yes
A9: U0177 | B9: 32 | C9: Male | D9: Philippines | E9: Professional | F9: High School | G9: Social Media Content Creator | H9: 486 | I9: ChatGPT | J9: Content Creation | K9: 2 | L9: Creating Instagram/TikTok captions with AI writing tools, Generating YouTube thumbnails and video descriptions using AI design assistants, Editing photos and videos with AI-powered software | M9: 0 | N9: 6.5 | O9: 2 | P9: 5 | Q9: 3.2 hrs | R9: 6.4 | S9: Yes
A10: U0207 | B10: 16 | C10: Male | D10: Philippines | E10: Student | F10: Undergraduate | G10: Digital Media Production Student | H10: 132 | I10: Claude | J10: Content Creation | K10: 1.6 hrs | L10: Creating YouTube video scripts, Designing social media graphics with AI image generators, Writing blog content for tech topics | M10: 30 | N10: 4.7 | O10: 4 | P10: 6 | Q10: 3.8 | R10: 3.8 | S10: Yes
A11: U0167 | B11: 40 | C11: male | D11: india | E11: Professional | F11: High School | H11: 1595 | I11: ChatGPT | J11: Writing | K11: 1.7 | L11: Email copywriting, Social media post creation, Blog article drafting, Product description writing | M11: 10 | O11: 2 | P11: 5 | Q11: 7.5 | R11: 9.4 | S11: Maybe
A12: U0135 | B12: 36 | C12: Female | D12: Pakistan | E12: Professional | F12: Master's | G12: Research Analyst | H12: 856 | I12: chatgpt | J12: Research | K12: 2.7 | L12: Literature review and synthesis using AI-powered databases, Data analysis and pattern recognition, Research paper writing and academic content generation | M12: 0 | O12: 4 | P12: 6 | Q12: 5.7 | R12: 8.7 | S12: Yes
A13: U0211 | B13: 22 | C13: Male | D13: Canada | E13: Student | F13: Undergraduate | G13: Mechanical Engineering Student | H13: 547 | I13: Claude | J13: Research | K13: 5 | L13: Literature review and paper summarization, Data analysis for lab experiments, Generating research hypotheses, Technical documentation and report writing | M13: 0 | N13: 6.6 | O13: 3 | P13: 6 | Q13: 9.8 | R13: 5.6 | S13: No
A14: U0114 | B14: 30 | C14: Female | D14: Australia | E14: Professional | F14: Bachelor's | G14: Software Developer | H14: 3307 | I14: ChatGPT | J14: Coding | K14: 0.8 | L14: Using AI code completion tools for writing Python functions, debugging code with AI-assisted analysis, generating unit test cases with AI tools | M14: 10 | N14: 2.3 | O14: 4 | P14: 4 | Q14: 0.5 | R14: 8 | S14: No
A15: U0191 | B15: 21 | C15: Female | D15: canada | E15: Student | F15: Undergraduate | G15: Software Engineering Student | H15: 387 | I15: ChatGPT | J15: Coding | K15: 5.8 | L15: Debugging code with AI assistance, generating code snippets for assignments, learning programming concepts through AI explanations | M15: 30 | N15: 6.9 | O15: 4 | P15: 8 | Q15: 10.2 | R15: 4.8 | S15: Yes
A16: U0035 | B16: 28 | C16: Male | D16: United Kingdom | E16: Professional | F16: Bachelor's | G16: Data Analyst | H16: 3117 | I16: Claude | J16: Data Analysis | K16: 3.9 | L16: Automated data cleaning and processing with Python scripts, building predictive models using machine learning algorithms, generating interactive dashboards and visualizations in Power BI | M16: 10 | N16: 8.6 | O16: 3 | P16: 8 | Q16: 11.8 | R16: 7.6 hrs | S16: Yes
A17: U0138 | B17: 16 yrs | C17: Female | D17: Canada | E17: Student | F17: Master's | H17: 324 | I17: Microsoft Copilot | J17: Coding | K17: 7.1 | M17: 20 | O17: 2 | P17: 5 | Q17: 11.6 | R17: 3 | S17: No
A18: U0059 | B18: 22 | C18: Male | D18: Canada | E18: Professional | F18: High School | G18: Customer Service Representative | H18: 3546 | I18: Perplexity AI | J18: Customer Support | K18: 1.7 | L18: Responding to customer inquiries via AI chatbots, drafting personalized support emails using AI writing assistants, resolving common technical issues with AI-guided troubleshooting scripts | M18: 0 | N18: 7 | O18: 4 | P18: 7 | Q18: 3.4 | R18: 6.7 | S18: Yes
A19: U0215 | B19: 23 | C19: Male | D19: India | E19: Student | F19: Master's | G19: English Literature Student | H19: 109 | I19: Google Gemini | J19: Writing | K19: 1.5 | L19: Drafting research papers on literary analysis, brainstorming essay outlines, proofreading and refining academic writing, generating content summaries for thesis work | M19: 20 | N19: 3.9 | O19: 3 | P19: 6 | Q19: 3.7 | R19: 3.9 | S19: Yes
A20: U0228 | B20: 22 | C20: male | D20: Kenya | E20: Student | F20: High School | G20: Biology Student | H20: 109 | I20: ChatGPT | J20: Research | K20: 9.6 | L20: Literature review for lab reports, summarizing research papers on molecular genetics, generating study notes from scientific articles | M20: 20 | N20: 7.3 | O20: 4 | P20: 9 | Q20: 19.4 | R20: 5.2 | S20: Yes
A21: U0046 | B21: 61 | C21: Female | D21: Nigeria | E21: Professional | F21: Diploma | G21: Research Technician | H21: 585 | I21: Google Gemini | J21: Research | K21: 23 | L21: Literature review synthesis using AI search tools, Data analysis and statistical reporting with AI-assisted tools, Survey data organization and preliminary findings documentation | M21: 10 | N21: 4.1 | O21: 3 | P21: 4 | Q21: 5.4 | R21: 9.5 | S21: No
A22: U0176 | B22: 24 | C22: Male | D22: India | E22: Professional | F22: Diploma | G22: AI-Powered Customer Support Executive | H22: 1977 | I22: ChatGPT | J22: Customer Support | K22: 0.9 | L22: AI chatbot management and customer query routing, multilingual customer response handling using AI tools, customer complaint analysis and resolution tracking | M22: 10 | N22: 4.1 | O22: 3 | P22: 6 | Q22: 0 | R22: 7.3 | S22: Maybe
A23: U0227 | B23: 23 | C23: M | D23: Pakistan | E23: Student | F23: Master's | G23: English Literature Student | H23: 0 | I23: ChatGPT | J23: Writing | K23: 1.7 hrs | L23: Essay structuring and outline generation, thesis statement refinement, academic paper proofreading and grammar checking, creative writing brainstorming | M23: 20 | N23: 2.8 | O23: 2 | P23: 3 | Q23: 2.7 | R23: 5.4 | S23: No
A24: U0198 | B24: 29 | C24: Female | D24: Germany | E24: Professional | F24: Bachelor's | G24: Kundenservice-Spezialistin / Customer Service Specialist | I24: ChatGPT | J24: Customer Support | K24: 1 | N24: 4 | O24: 3 | P24: 6 | Q24: 2.7 | R24: 8 | S24: Maybe
